> Initialized logger
>  * Debugger is active!
>  * Debugger PIN: 456-115-780
>  * Running on http://0.0.0.0:80/ (Press CTRL+C to quit)
> 192.168.137.67 - - [24/Feb/2019 16:41:25] "POST /api/validation/ HTTP/1.1" 200 -
> 192.168.137.67 - - [24/Feb/2019 16:41:26] "POST /api/validation/ HTTP/1.1" 500 -
> Traceback (most recent call last):
>   File "C:\Users\gherz-PC\Anaconda3\envs\py27\lib\site-packages\flask\app.py", line 2309, in __call__
>     return self.wsgi_app(environ, start_response)
>   File "C:\Users\gherz-PC\Anaconda3\envs\py27\lib\site-packages\flask\app.py", line 2295, in wsgi_app
>     response = self.handle_exception(e)
>   File "C:\Users\gherz-PC\Anaconda3\envs\py27\lib\site-packages\flask\app.py", line 1741, in handle_exception
>     reraise(exc_type, exc_value, tb)
>   File "C:\Users\gherz-PC\Anaconda3\envs\py27\lib\site-packages\flask\app.py", line 2292, in wsgi_app
>     response = self.full_dispatch_request()
>   File "C:\Users\gherz-PC\Anaconda3\envs\py27\lib\site-packages\flask\app.py", line 1815, in full_dispatch_request
>     rv = self.handle_user_exception(e)
>   File "C:\Users\gherz-PC\Anaconda3\envs\py27\lib\site-packages\flask\app.py", line 1718, in handle_user_exception
>     reraise(exc_type, exc_value, tb)
>   File "C:\Users\gherz-PC\Anaconda3\envs\py27\lib\site-packages\flask\app.py", line 1813, in full_dispatch_request
>     rv = self.dispatch_request()
>   File "C:\Users\gherz-PC\Anaconda3\envs\py27\lib\site-packages\flask\app.py", line 1799, in dispatch_request
>     return self.view_functions[rule.endpoint](**req.view_args)
>   File "C:\Users\gherz-PC\Desktop\remidiv2\serveus\views.py", line 1403, in update_validation
>     filenames = request.form['string']
>   File "C:\Users\gherz-PC\Anaconda3\envs\py27\lib\site-packages\werkzeug\datastructures.py", line 431, in __getitem__
>     raise exceptions.BadRequestKeyError(key)
> BadRequestKeyError: 400 Bad Request: KeyError: 'string'
> 192.168.137.67 - - [24/Feb/2019 16:41:26] "POST /api/db/ HTTP/1.1" 200 -
> 192.168.137.67 - - [24/Feb/2019 18:32:57] "POST /api/db/ HTTP/1.1" 500 -
> Traceback (most recent call last):
>   File "C:\Users\gherz-PC\Anaconda3\envs\py27\lib\site-packages\flask\app.py", line 2309, in __call__
>     return self.wsgi_app(environ, start_response)
>   File "C:\Users\gherz-PC\Anaconda3\envs\py27\lib\site-packages\flask\app.py", line 2295, in wsgi_app
>     response = self.handle_exception(e)
>   File "C:\Users\gherz-PC\Anaconda3\envs\py27\lib\site-packages\flask\app.py", line 1741, in handle_exception
>     reraise(exc_type, exc_value, tb)
>   File "C:\Users\gherz-PC\Anaconda3\envs\py27\lib\site-packages\flask\app.py", line 2292, in wsgi_app
>     response = self.full_dispatch_request()
>   File "C:\Users\gherz-PC\Anaconda3\envs\py27\lib\site-packages\flask\app.py", line 1815, in full_dispatch_request
>     rv = self.handle_user_exception(e)
>   File "C:\Users\gherz-PC\Anaconda3\envs\py27\lib\site-packages\flask\app.py", line 1718, in handle_user_exception
>     reraise(exc_type, exc_value, tb)
>   File "C:\Users\gherz-PC\Anaconda3\envs\py27\lib\site-packages\flask\app.py", line 1813, in full_dispatch_request
>     rv = self.dispatch_request()
>   File "C:\Users\gherz-PC\Anaconda3\envs\py27\lib\site-packages\flask\app.py", line 1799, in dispatch_request
>     return self.view_functions[rule.endpoint](**req.view_args)
>   File "C:\Users\gherz-PC\Desktop\remidiv2\serveus\views.py", line 962, in update_db
>     c.execute("DELETE FROM user")
> OperationalError: no such table: user
> 192.168.137.67 - - [24/Feb/2019 18:41:55] "POST /api/db/ HTTP/1.1" 500 -
> Traceback (most recent call last):
>   File "C:\Users\gherz-PC\Anaconda3\envs\py27\lib\site-packages\flask\app.py", line 2309, in __call__
>     return self.wsgi_app(environ, start_response)
>   File "C:\Users\gherz-PC\Anaconda3\envs\py27\lib\site-packages\flask\app.py", line 2295, in wsgi_app
>     response = self.handle_exception(e)
>   File "C:\Users\gherz-PC\Anaconda3\envs\py27\lib\site-packages\flask\app.py", line 1741, in handle_exception
>     reraise(exc_type, exc_value, tb)
>   File "C:\Users\gherz-PC\Anaconda3\envs\py27\lib\site-packages\flask\app.py", line 2292, in wsgi_app
>     response = self.full_dispatch_request()
>   File "C:\Users\gherz-PC\Anaconda3\envs\py27\lib\site-packages\flask\app.py", line 1815, in full_dispatch_request
>     rv = self.handle_user_exception(e)
>   File "C:\Users\gherz-PC\Anaconda3\envs\py27\lib\site-packages\flask\app.py", line 1718, in handle_user_exception
>     reraise(exc_type, exc_value, tb)
>   File "C:\Users\gherz-PC\Anaconda3\envs\py27\lib\site-packages\flask\app.py", line 1813, in full_dispatch_request
>     rv = self.dispatch_request()
>   File "C:\Users\gherz-PC\Anaconda3\envs\py27\lib\site-packages\flask\app.py", line 1799, in dispatch_request
>     return self.view_functions[rule.endpoint](**req.view_args)
>   File "C:\Users\gherz-PC\Desktop\remidiv2\serveus\views.py", line 962, in update_db
>     c.execute("DELETE FROM user")
> OperationalError: no such table: user
> 192.168.137.67 - - [24/Feb/2019 18:41:56] "POST /api/db/ HTTP/1.1" 500 -
> Traceback (most recent call last):
>   File "C:\Users\gherz-PC\Anaconda3\envs\py27\lib\site-packages\flask\app.py", line 2309, in __call__
>     return self.wsgi_app(environ, start_response)
>   File "C:\Users\gherz-PC\Anaconda3\envs\py27\lib\site-packages\flask\app.py", line 2295, in wsgi_app
>     response = self.handle_exception(e)
>   File "C:\Users\gherz-PC\Anaconda3\envs\py27\lib\site-packages\flask\app.py", line 1741, in handle_exception
>     reraise(exc_type, exc_value, tb)
>   File "C:\Users\gherz-PC\Anaconda3\envs\py27\lib\site-packages\flask\app.py", line 2292, in wsgi_app
>     response = self.full_dispatch_request()
>   File "C:\Users\gherz-PC\Anaconda3\envs\py27\lib\site-packages\flask\app.py", line 1815, in full_dispatch_request
>     rv = self.handle_user_exception(e)
>   File "C:\Users\gherz-PC\Anaconda3\envs\py27\lib\site-packages\flask\app.py", line 1718, in handle_user_exception
>     reraise(exc_type, exc_value, tb)
>   File "C:\Users\gherz-PC\Anaconda3\envs\py27\lib\site-packages\flask\app.py", line 1813, in full_dispatch_request
>     rv = self.dispatch_request()
>   File "C:\Users\gherz-PC\Anaconda3\envs\py27\lib\site-packages\flask\app.py", line 1799, in dispatch_request
>     return self.view_functions[rule.endpoint](**req.view_args)
>   File "C:\Users\gherz-PC\Desktop\remidiv2\serveus\views.py", line 962, in update_db
>     c.execute("DELETE FROM user")
> OperationalError: no such table: user
> 127.0.0.1 - - [24/Feb/2019 18:42:46] "GET / HTTP/1.1" 302 -
> 127.0.0.1 - - [24/Feb/2019 18:42:47] "GET /monitoring/1/ HTTP/1.1" 200 -
> 127.0.0.1 - - [24/Feb/2019 18:42:48] "GET /static/js/jquery.js HTTP/1.1" 200 -
> 192.168.137.67 - - [24/Feb/2019 18:43:31] "POST /api/db/ HTTP/1.1" 500 -
> Traceback (most recent call last):
>   File "C:\Users\gherz-PC\Anaconda3\envs\py27\lib\site-packages\flask\app.py", line 2309, in __call__
>     return self.wsgi_app(environ, start_response)
>   File "C:\Users\gherz-PC\Anaconda3\envs\py27\lib\site-packages\flask\app.py", line 2295, in wsgi_app
>     response = self.handle_exception(e)
>   File "C:\Users\gherz-PC\Anaconda3\envs\py27\lib\site-packages\flask\app.py", line 1741, in handle_exception
>     reraise(exc_type, exc_value, tb)
>   File "C:\Users\gherz-PC\Anaconda3\envs\py27\lib\site-packages\flask\app.py", line 2292, in wsgi_app
>     response = self.full_dispatch_request()
>   File "C:\Users\gherz-PC\Anaconda3\envs\py27\lib\site-packages\flask\app.py", line 1815, in full_dispatch_request
>     rv = self.handle_user_exception(e)
>   File "C:\Users\gherz-PC\Anaconda3\envs\py27\lib\site-packages\flask\app.py", line 1718, in handle_user_exception
>     reraise(exc_type, exc_value, tb)
>   File "C:\Users\gherz-PC\Anaconda3\envs\py27\lib\site-packages\flask\app.py", line 1813, in full_dispatch_request
>     rv = self.dispatch_request()
>   File "C:\Users\gherz-PC\Anaconda3\envs\py27\lib\site-packages\flask\app.py", line 1799, in dispatch_request
>     return self.view_functions[rule.endpoint](**req.view_args)
>   File "C:\Users\gherz-PC\Desktop\remidiv2\serveus\views.py", line 962, in update_db
>     c.execute("DELETE FROM user")
> OperationalError: no such table: user
> 192.168.137.67 - - [24/Feb/2019 18:43:32] "POST /api/db/ HTTP/1.1" 500 -
> Traceback (most recent call last):
>   File "C:\Users\gherz-PC\Anaconda3\envs\py27\lib\site-packages\flask\app.py", line 2309, in __call__
>     return self.wsgi_app(environ, start_response)
>   File "C:\Users\gherz-PC\Anaconda3\envs\py27\lib\site-packages\flask\app.py", line 2295, in wsgi_app
>     response = self.handle_exception(e)
>   File "C:\Users\gherz-PC\Anaconda3\envs\py27\lib\site-packages\flask\app.py", line 1741, in handle_exception
>     reraise(exc_type, exc_value, tb)
>   File "C:\Users\gherz-PC\Anaconda3\envs\py27\lib\site-packages\flask\app.py", line 2292, in wsgi_app
>     response = self.full_dispatch_request()
>   File "C:\Users\gherz-PC\Anaconda3\envs\py27\lib\site-packages\flask\app.py", line 1815, in full_dispatch_request
>     rv = self.handle_user_exception(e)
>   File "C:\Users\gherz-PC\Anaconda3\envs\py27\lib\site-packages\flask\app.py", line 1718, in handle_user_exception
>     reraise(exc_type, exc_value, tb)
>   File "C:\Users\gherz-PC\Anaconda3\envs\py27\lib\site-packages\flask\app.py", line 1813, in full_dispatch_request
>     rv = self.dispatch_request()
>   File "C:\Users\gherz-PC\Anaconda3\envs\py27\lib\site-packages\flask\app.py", line 1799, in dispatch_request
>     return self.view_functions[rule.endpoint](**req.view_args)
>   File "C:\Users\gherz-PC\Desktop\remidiv2\serveus\views.py", line 962, in update_db
>     c.execute("DELETE FROM user")
> OperationalError: no such table: user
> 192.168.137.67 - - [24/Feb/2019 18:43:35] "POST /api/db/ HTTP/1.1" 500 -
> Traceback (most recent call last):
>   File "C:\Users\gherz-PC\Anaconda3\envs\py27\lib\site-packages\flask\app.py", line 2309, in __call__
>     return self.wsgi_app(environ, start_response)
>   File "C:\Users\gherz-PC\Anaconda3\envs\py27\lib\site-packages\flask\app.py", line 2295, in wsgi_app
>     response = self.handle_exception(e)
>   File "C:\Users\gherz-PC\Anaconda3\envs\py27\lib\site-packages\flask\app.py", line 1741, in handle_exception
>     reraise(exc_type, exc_value, tb)
>   File "C:\Users\gherz-PC\Anaconda3\envs\py27\lib\site-packages\flask\app.py", line 2292, in wsgi_app
>     response = self.full_dispatch_request()
>   File "C:\Users\gherz-PC\Anaconda3\envs\py27\lib\site-packages\flask\app.py", line 1815, in full_dispatch_request
>     rv = self.handle_user_exception(e)
>   File "C:\Users\gherz-PC\Anaconda3\envs\py27\lib\site-packages\flask\app.py", line 1718, in handle_user_exception
>     reraise(exc_type, exc_value, tb)
>   File "C:\Users\gherz-PC\Anaconda3\envs\py27\lib\site-packages\flask\app.py", line 1813, in full_dispatch_request
>     rv = self.dispatch_request()
>   File "C:\Users\gherz-PC\Anaconda3\envs\py27\lib\site-packages\flask\app.py", line 1799, in dispatch_request
>     return self.view_functions[rule.endpoint](**req.view_args)
>   File "C:\Users\gherz-PC\Desktop\remidiv2\serveus\views.py", line 962, in update_db
>     c.execute("DELETE FROM user")
> OperationalError: no such table: user
