> Initialized logger
>  * Debugger is active!
>  * Debugger PIN: 456-115-780
>  * Running on http://0.0.0.0:80/ (Press CTRL+C to quit)
> 192.168.137.224 - - [24/Feb/2019 22:50:48] "POST /api/validation/ HTTP/1.1" 200 -
> 192.168.137.224 - - [24/Feb/2019 22:50:49] "POST /api/validation/ HTTP/1.1" 500 -
> Traceback (most recent call last):
>   File "C:\Users\gherz-PC\Anaconda3\envs\py27\lib\site-packages\flask\app.py", line 2309, in __call__
>     return self.wsgi_app(environ, start_response)
>   File "C:\Users\gherz-PC\Anaconda3\envs\py27\lib\site-packages\flask\app.py", line 2295, in wsgi_app
>     response = self.handle_exception(e)
>   File "C:\Users\gherz-PC\Anaconda3\envs\py27\lib\site-packages\flask\app.py", line 1741, in handle_exception
>     reraise(exc_type, exc_value, tb)
>   File "C:\Users\gherz-PC\Anaconda3\envs\py27\lib\site-packages\flask\app.py", line 2292, in wsgi_app
>     response = self.full_dispatch_request()
>   File "C:\Users\gherz-PC\Anaconda3\envs\py27\lib\site-packages\flask\app.py", line 1816, in full_dispatch_request
>     return self.finalize_request(rv)
>   File "C:\Users\gherz-PC\Anaconda3\envs\py27\lib\site-packages\flask\app.py", line 1831, in finalize_request
>     response = self.make_response(rv)
>   File "C:\Users\gherz-PC\Anaconda3\envs\py27\lib\site-packages\flask\app.py", line 1982, in make_response
>     reraise(TypeError, new_error, sys.exc_info()[2])
>   File "C:\Users\gherz-PC\Anaconda3\envs\py27\lib\site-packages\flask\app.py", line 1974, in make_response
>     rv = self.response_class.force_type(rv, request.environ)
>   File "C:\Users\gherz-PC\Anaconda3\envs\py27\lib\site-packages\werkzeug\wrappers.py", line 921, in force_type
>     response = BaseResponse(*_run_wsgi_app(response, environ))
>   File "C:\Users\gherz-PC\Anaconda3\envs\py27\lib\site-packages\werkzeug\wrappers.py", line 59, in _run_wsgi_app
>     return _run_wsgi_app(*args)
>   File "C:\Users\gherz-PC\Anaconda3\envs\py27\lib\site-packages\werkzeug\test.py", line 923, in run_wsgi_app
>     app_rv = app(environ, start_response)
> TypeError: 'dict' object is not callable
> The view function did not return a valid response. The return type must be a string, tuple, Response instance, or WSGI callable, but it was a dict.
> 192.168.137.224 - - [24/Feb/2019 22:50:49] "POST /api/db/ HTTP/1.1" 200 -
>  * Detected change in 'C:\\Users\\gherz-PC\\Desktop\\remidiv2\\serveus\\views.py', reloading
