> Initialized logger
>  * Debugger is active!
>  * Debugger PIN: 456-115-780
>  * Running on http://0.0.0.0:80/ (Press CTRL+C to quit)
> 192.168.137.31 - - [13/Mar/2019 10:21:03] "POST /api/validation/ HTTP/1.1" 200 -
> 192.168.137.31 - - [13/Mar/2019 10:21:03] "POST /api/validation/ HTTP/1.1" 200 -
> 192.168.137.31 - - [13/Mar/2019 10:21:07] "POST /api/validation/ HTTP/1.1" 200 -
> 192.168.137.31 - - [13/Mar/2019 10:21:07] "POST /api/validation/ HTTP/1.1" 200 -
> 192.168.137.31 - - [13/Mar/2019 10:21:07] "POST /api/db/ HTTP/1.1" 500 -
> Traceback (most recent call last):
>   File "C:\Users\gherz-PC\Anaconda3\envs\py27\lib\site-packages\flask\app.py", line 2309, in __call__
>     return self.wsgi_app(environ, start_response)
>   File "C:\Users\gherz-PC\Anaconda3\envs\py27\lib\site-packages\flask\app.py", line 2295, in wsgi_app
>     response = self.handle_exception(e)
>   File "C:\Users\gherz-PC\Anaconda3\envs\py27\lib\site-packages\flask\app.py", line 1741, in handle_exception
>     reraise(exc_type, exc_value, tb)
>   File "C:\Users\gherz-PC\Anaconda3\envs\py27\lib\site-packages\flask\app.py", line 2292, in wsgi_app
>     response = self.full_dispatch_request()
>   File "C:\Users\gherz-PC\Anaconda3\envs\py27\lib\site-packages\flask\app.py", line 1815, in full_dispatch_request
>     rv = self.handle_user_exception(e)
>   File "C:\Users\gherz-PC\Anaconda3\envs\py27\lib\site-packages\flask\app.py", line 1718, in handle_user_exception
>     reraise(exc_type, exc_value, tb)
>   File "C:\Users\gherz-PC\Anaconda3\envs\py27\lib\site-packages\flask\app.py", line 1813, in full_dispatch_request
>     rv = self.dispatch_request()
>   File "C:\Users\gherz-PC\Anaconda3\envs\py27\lib\site-packages\flask\app.py", line 1799, in dispatch_request
>     return self.view_functions[rule.endpoint](**req.view_args)
>   File "C:\Users\gherz-PC\Desktop\remidiv2\serveus\views.py", line 966, in update_db
>     if Database.need_update(date_string):
>   File "C:\Users\gherz-PC\Desktop\remidiv2\serveus\models.py", line 259, in need_update
>     print("Last modified: " + Database.query.first().modified)
> TypeError: cannot concatenate 'str' and 'datetime.datetime' objects
>  * Detected change in 'C:\\Users\\gherz-PC\\Desktop\\remidiv2\\serveus\\models.py', reloading
